2019-04-30 17:16:51,607 - server.py - INFO - Starting server at address ('127.0.0.1', 9999)
2019-04-30 17:16:51,608 - server.py - INFO - Server started
2019-04-30 17:16:51,609 - tests.py - INFO - wait server...
2019-04-30 17:16:51,718 - tests.py - DEBUG - 127.0.0.1 wrote: b'BOOM!!!'
2019-04-30 17:16:51,718 - server.py - ERROR - ----------------------------------------
2019-04-30 17:16:51,718 - server.py - ERROR - Exception happened during processing of request from ('127.0.0.1', 45544)
Traceback (most recent call last):
  File "/home/depaolim/.pyenv/versions/3.6.8/lib/python3.6/socketserver.py", line 320, in _handle_request_noblock
    self.process_request(request, client_address)
  File "/home/depaolim/.pyenv/versions/3.6.8/lib/python3.6/socketserver.py", line 351, in process_request
    self.finish_request(request, client_address)
  File "/home/depaolim/.pyenv/versions/3.6.8/lib/python3.6/socketserver.py", line 364, in finish_request
    self.RequestHandlerClass(request, client_address, self)
  File "/home/depaolim/.pyenv/versions/3.6.8/lib/python3.6/socketserver.py", line 724, in __init__
    self.handle()
  File "/home/depaolim/Projects/Jelly/test/tests.py", line 32, in handle
    raise MyException("BOOM!!!")
test.tests.MyException: BOOM!!!
2019-04-30 17:16:51,719 - server.py - ERROR - ----------------------------------------
2019-04-30 17:16:51,719 - tests.py - INFO - shutdown...
2019-04-30 17:16:52,220 - tests.py - INFO - close...
2019-04-30 17:16:52,220 - server.py - INFO - Shutting down server at address ('127.0.0.1', 9999)
2019-04-30 17:16:52,220 - server.py - INFO - Server stopped
2019-04-30 17:16:52,221 - tests.py - INFO - join...
